Gym has been unmaintained since 2022 and does not support NumPy 2.0 amongst other critical functionality.
Please upgrade to Gymnasium, the maintained drop-in replacement of Gym, or contact the authors of your software and request that they upgrade.
Users of this version of Gym should be able to simply replace 'import gym' with 'import gymnasium as gym' in the vast majority of cases.
See the migration guide at https://gymnasium.farama.org/introduction/migration_guide/ for additional information.
[Bridge] Mineflayer bridge server running on port 3333
[Bot] Logged in to server
[Bot] Spawned in world
[Bot] Spawned! Waiting for chunks to load before init viewer...
[Bot] Initializing viewer...
[Viewer] Initializing...
Using version: 1.21.4
[Viewer] Version set: 1.21.8
[Viewer] Center: Vec3 { x: -614.5, y: 72, z: -522.5 }
[Viewer] Initializing world view...
[Server] Connecting bot to Minecraft server at 2.tcp.us-cal-1.ngrok.io:19335
[MineflayerEnv] Bridge server started on port 3333
[MineflayerEnv] Bot 'JarvisAI' connecting to 2.tcp.us-cal-1.ngrok.io:19335
[MineflayerEnv] Waiting for bot to spawn and viewer to initialize...
[MineflayerEnv] ✓ Bot connected and ready
[Server] Initializing VLLM agent from CraftJarvis/JarvisVLA-Qwen2-VL-7B
[05:36:17] tokenizer_type: qwen2_vl                                                                                                                                   action_mapping.py:356
[05:36:17] bases: [10, 3, 3, 3, 2, 2, 2, 2, 2, 2, 21, 21], camera_mu: 20, n_camera_bins: 21, camera_binsize: 1                                                        action_mapping.py:357
[Viewer] World view initialized
[Viewer] ✓ Screenshot support ready
Traceback (most recent call last):
  File "/usr/local/lib/python3.11/dist-packages/httpx/_transports/default.py", line 101, in map_httpcore_exceptions
    yield
  File "/usr/local/lib/python3.11/dist-packages/httpx/_transports/default.py", line 250, in handle_request
    resp = self._pool.handle_request(req)
           ^^^^^^^^^^^^^^^^^^^^^^^^^^^^^^
  File "/usr/local/lib/python3.11/dist-packages/httpcore/_sync/connection_pool.py", line 256, in handle_request
    raise exc from None
  File "/usr/local/lib/python3.11/dist-packages/httpcore/_sync/connection_pool.py", line 236, in handle_request
    response = connection.handle_request(
               ^^^^^^^^^^^^^^^^^^^^^^^^^^
  File "/usr/local/lib/python3.11/dist-packages/httpcore/_sync/connection.py", line 101, in handle_request
    raise exc
  File "/usr/local/lib/python3.11/dist-packages/httpcore/_sync/connection.py", line 78, in handle_request
    stream = self._connect(request)
             ^^^^^^^^^^^^^^^^^^^^^^
  File "/usr/local/lib/python3.11/dist-packages/httpcore/_sync/connection.py", line 124, in _connect
    stream = self._network_backend.connect_tcp(**kwargs)
             ^^^^^^^^^^^^^^^^^^^^^^^^^^^^^^^^^^^^^^^^^^^
  File "/usr/local/lib/python3.11/dist-packages/httpcore/_backends/sync.py", line 207, in connect_tcp
    with map_exceptions(exc_map):
  File "/usr/lib/python3.11/contextlib.py", line 158, in __exit__
    self.gen.throw(typ, value, traceback)
  File "/usr/local/lib/python3.11/dist-packages/httpcore/_exceptions.py", line 14, in map_exceptions
    raise to_exc(exc) from exc
httpcore.ConnectError: [Errno 111] Connection refused

The above exception was the direct cause of the following exception:

Traceback (most recent call last):
  File "/usr/local/lib/python3.11/dist-packages/openai/_base_client.py", line 982, in request
    response = self._client.send(
               ^^^^^^^^^^^^^^^^^^
  File "/usr/local/lib/python3.11/dist-packages/httpx/_client.py", line 914, in send
    response = self._send_handling_auth(
               ^^^^^^^^^^^^^^^^^^^^^^^^^
  File "/usr/local/lib/python3.11/dist-packages/httpx/_client.py", line 942, in _send_handling_auth
    response = self._send_handling_redirects(
               ^^^^^^^^^^^^^^^^^^^^^^^^^^^^^^
  File "/usr/local/lib/python3.11/dist-packages/httpx/_client.py", line 979, in _send_handling_redirects
    response = self._send_single_request(request)
               ^^^^^^^^^^^^^^^^^^^^^^^^^^^^^^^^^^
  File "/usr/local/lib/python3.11/dist-packages/httpx/_client.py", line 1014, in _send_single_request
    response = transport.handle_request(request)
               ^^^^^^^^^^^^^^^^^^^^^^^^^^^^^^^^^
  File "/usr/local/lib/python3.11/dist-packages/httpx/_transports/default.py", line 249, in handle_request
    with map_httpcore_exceptions():
  File "/usr/lib/python3.11/contextlib.py", line 158, in __exit__
    self.gen.throw(typ, value, traceback)
  File "/usr/local/lib/python3.11/dist-packages/httpx/_transports/default.py", line 118, in map_httpcore_exceptions
    raise mapped_exc(message) from exc
httpx.ConnectError: [Errno 111] Connection refused

The above exception was the direct cause of the following exception:

Traceback (most recent call last):
  File "/workspace/Herobine/bridge/server_mineflayer.py", line 287, in <module>
    main()
  File "/workspace/Herobine/bridge/server_mineflayer.py", line 262, in main
    server = MinecraftAIServer(
             ^^^^^^^^^^^^^^^^^^
  File "/workspace/Herobine/bridge/server_mineflayer.py", line 73, in __init__
    self.agent = VLLMAgentAdapter(
                 ^^^^^^^^^^^^^^^^^
  File "/workspace/Herobine/bridge/vllm_agent_adapter.py", line 41, in __init__
    self.agent = agent_wrapper.VLLM_AGENT(
                 ^^^^^^^^^^^^^^^^^^^^^^^^^
  File "/workspace/Herobine/JarvisVLA/jarvisvla/evaluate/agent_wrapper.py", line 63, in __init__
    models = self.client.models.list()
             ^^^^^^^^^^^^^^^^^^^^^^^^^
  File "/usr/local/lib/python3.11/dist-packages/openai/resources/models.py", line 91, in list
    return self._get_api_list(
           ^^^^^^^^^^^^^^^^^^^
  File "/usr/local/lib/python3.11/dist-packages/openai/_base_client.py", line 1308, in get_api_list
    return self._request_api_list(model, page, opts)
           ^^^^^^^^^^^^^^^^^^^^^^^^^^^^^^^^^^^^^^^^^
  File "/usr/local/lib/python3.11/dist-packages/openai/_base_client.py", line 1159, in _request_api_list
    return self.request(page, options, stream=False)
           ^^^^^^^^^^^^^^^^^^^^^^^^^^^^^^^^^^^^^^^^^
  File "/usr/local/lib/python3.11/dist-packages/openai/_base_client.py", line 1014, in request
    raise APIConnectionError(request=request) from err
openai.APIConnectionError: Connection error.
[MineflayerEnv] Bridge server stopped
